Traceback (most recent call last):
  File "/home/tharikh/anaconda3/lib/python3.8/site-packages/wandb/sdk/wandb_config.py", line 166, in __getattr__
    return self.__getitem__(key)
  File "/home/tharikh/anaconda3/lib/python3.8/site-packages/wandb/sdk/wandb_config.py", line 133, in __getitem__
    return self._items[key]
KeyError: 'hidden_size'
The above exception was the direct cause of the following exception:
Traceback (most recent call last):
  File "main.py", line 65, in <module>
    wandb.run.name = f'hln_{num_hidden_layer}_hls_{wandb.config.hidden_size}_hla_{hidden_layer_activation}_winit_{weight_name}_ep_{epochs}_op_{optimizer_name}_lr_{lr}_bs_{batch_size}_wd_{weight_decay}_ln_{loss_name}'
  File "/home/tharikh/anaconda3/lib/python3.8/site-packages/wandb/sdk/wandb_config.py", line 168, in __getattr__
    raise AttributeError(
AttributeError: <class 'wandb.sdk.wandb_config.Config'> object has no attribute 'hidden_size'