2023-03-17 16:51:06,214 INFO    StreamThr :77148 [internal.py:wandb_internal():87] W&B internal server running at pid: 77148, started at: 2023-03-17 16:51:06.213666
2023-03-17 16:51:06,216 DEBUG   HandlerThread:77148 [handler.py:handle_request():144] handle_request: status
2023-03-17 16:51:06,224 INFO    WriterThread:77148 [datastore.py:open_for_write():85] open: /home/tharikh/dl-ass-1/wandb/run-20230317_165106-729xs2rs/run-729xs2rs.wandb
2023-03-17 16:51:06,224 DEBUG   SenderThread:77148 [sender.py:send():336] send: header
2023-03-17 16:51:06,250 DEBUG   SenderThread:77148 [sender.py:send():336] send: run
2023-03-17 16:51:07,165 ERROR   SenderThread:77148 [internal_api.py:execute():245] 403 response executing GraphQL.
2023-03-17 16:51:07,166 ERROR   SenderThread:77148 [internal_api.py:execute():246] {"errors":[{"message":"permission denied","path":["upsertBucket"],"extensions":{"code":"PERMISSION_ERROR"}}],"data":{"upsertBucket":null}}
2023-03-17 16:51:07,250 INFO    HandlerThread:77148 [handler.py:finish():841] shutting down handler
2023-03-17 16:51:07,251 INFO    WriterThread:77148 [datastore.py:close():299] close: /home/tharikh/dl-ass-1/wandb/run-20230317_165106-729xs2rs/run-729xs2rs.wandb
2023-03-17 16:51:07,251 ERROR   StreamThr :77148 [internal.py:wandb_internal():175] Thread SenderThread:
Traceback (most recent call last):
  File "/home/tharikh/anaconda3/lib/python3.8/site-packages/wandb/sdk/lib/retry.py", line 131, in __call__
    result = self._call_fn(*args, **kwargs)
  File "/home/tharikh/anaconda3/lib/python3.8/site-packages/wandb/sdk/internal/internal_api.py", line 242, in execute
    return self.client.execute(*args, **kwargs)  # type: ignore
  File "/home/tharikh/anaconda3/lib/python3.8/site-packages/wandb/vendor/gql-0.2.0/wandb_gql/client.py", line 52, in execute
    result = self._get_result(document, *args, **kwargs)
  File "/home/tharikh/anaconda3/lib/python3.8/site-packages/wandb/vendor/gql-0.2.0/wandb_gql/client.py", line 60, in _get_result
    return self.transport.execute(document, *args, **kwargs)
  File "/home/tharikh/anaconda3/lib/python3.8/site-packages/wandb/vendor/gql-0.2.0/wandb_gql/transport/requests.py", line 39, in execute
    request.raise_for_status()
  File "/home/tharikh/anaconda3/lib/python3.8/site-packages/requests/models.py", line 943, in raise_for_status
    raise HTTPError(http_error_msg, response=self)
requests.exceptions.HTTPError: 403 Client Error: Forbidden for url: https://api.wandb.ai/graphql

During handling of the above exception, another exception occurred:

Traceback (most recent call last):
  File "/home/tharikh/anaconda3/lib/python3.8/site-packages/wandb/apis/normalize.py", line 26, in wrapper
    return func(*args, **kwargs)
  File "/home/tharikh/anaconda3/lib/python3.8/site-packages/wandb/sdk/internal/internal_api.py", line 1593, in upsert_run
    response = self.gql(
  File "/home/tharikh/anaconda3/lib/python3.8/site-packages/wandb/sdk/internal/internal_api.py", line 214, in gql
    ret = self._retry_gql(
  File "/home/tharikh/anaconda3/lib/python3.8/site-packages/wandb/sdk/lib/retry.py", line 147, in __call__
    retry_timedelta_triggered = check_retry_fn(e)
  File "/home/tharikh/anaconda3/lib/python3.8/site-packages/wandb/util.py", line 1066, in check_retry_fn
    return fallback_retry_fn(e)
  File "/home/tharikh/anaconda3/lib/python3.8/site-packages/wandb/util.py", line 1013, in no_retry_auth
    raise CommError("Permission denied, ask the project owner to grant you access")
wandb.errors.CommError: Permission denied, ask the project owner to grant you access

During handling of the above exception, another exception occurred:

Traceback (most recent call last):
  File "/home/tharikh/anaconda3/lib/python3.8/site-packages/wandb/sdk/internal/internal_util.py", line 49, in run
    self._run()
  File "/home/tharikh/anaconda3/lib/python3.8/site-packages/wandb/sdk/internal/internal_util.py", line 100, in _run
    self._process(record)
  File "/home/tharikh/anaconda3/lib/python3.8/site-packages/wandb/sdk/internal/internal.py", line 329, in _process
    self._sm.send(record)
  File "/home/tharikh/anaconda3/lib/python3.8/site-packages/wandb/sdk/internal/sender.py", line 343, in send
    send_handler(record)
  File "/home/tharikh/anaconda3/lib/python3.8/site-packages/wandb/sdk/internal/sender.py", line 929, in send_run
    self._init_run(run, config_value_dict)
  File "/home/tharikh/anaconda3/lib/python3.8/site-packages/wandb/sdk/internal/sender.py", line 957, in _init_run
    server_run, inserted, server_messages = self._api.upsert_run(
  File "/home/tharikh/anaconda3/lib/python3.8/site-packages/wandb/apis/normalize.py", line 64, in wrapper
    raise CommError(message, err).with_traceback(sys.exc_info()[2])
  File "/home/tharikh/anaconda3/lib/python3.8/site-packages/wandb/apis/normalize.py", line 26, in wrapper
    return func(*args, **kwargs)
  File "/home/tharikh/anaconda3/lib/python3.8/site-packages/wandb/sdk/internal/internal_api.py", line 1593, in upsert_run
    response = self.gql(
  File "/home/tharikh/anaconda3/lib/python3.8/site-packages/wandb/sdk/internal/internal_api.py", line 214, in gql
    ret = self._retry_gql(
  File "/home/tharikh/anaconda3/lib/python3.8/site-packages/wandb/sdk/lib/retry.py", line 147, in __call__
    retry_timedelta_triggered = check_retry_fn(e)
  File "/home/tharikh/anaconda3/lib/python3.8/site-packages/wandb/util.py", line 1066, in check_retry_fn
    return fallback_retry_fn(e)
  File "/home/tharikh/anaconda3/lib/python3.8/site-packages/wandb/util.py", line 1013, in no_retry_auth
    raise CommError("Permission denied, ask the project owner to grant you access")
wandb.errors.CommError: Permission denied, ask the project owner to grant you access
